Workbook

Sheet google_form
A1: Timestamp | B1: Email Address | C1: Data category | D1: Product name | E1: Reference | F1: Citation | G1: Citation DOI | H1: Image URL | I1: Data access link | J1: Spatial resolution | K1: Temporal resolution | L1: Period | M1: Spatial domain | N1: Sampling type | O1: Highlights | P1: Description | Q1: Citation DOI status | R1: Data access status
A2: 45961.925 | C2: Data compilations | D2: SOCAT | E2: Bakker, D. C. E., Pfeil, B., Landa, C. S., Metzl, N., O'Brien, K. M., Olsen, A., Smith, K., Cosca, C., Harasawa, S., Jones, S. D., Nakaoka, S., Nojiri, Y., Schuster, U., Steinhoff, T., Sweeney, C., Takahashi, T., Tilbrook, B., Wada, C., Wanninkhof, R., Alin, S. R., Balestrini, C. F., Barbero, L., Bates, N. R., Bianchi, A. A., Bonou, F., Boutin, J., Bozec, Y., Burger, E. F., Cai, W.-J., Castle, R. D., Chen, L., Chierici, M., Currie, K., Evans, W., Featherstone, C., Feely, R. A., Fransson, A., Goyet, C., Greenwood, N., Gregor, L., Hankin, S., Hardman-Mountford, N. J., Harlay, J., Hauck, J., Hoppema, M., Humphreys, M. P., Hunt, C. W., Huss, B., Ibánhez, J. S. P., Johannessen, T., Keeling, R., Kitidis, V., Körtzinger, A., Kozyr, A., Krasakopoulou, E., Kuwata, A., Landschützer, P., Lauvset, S. K., Lefèvre, N., Lo Monaco, C., Manke, A., Mathis, J. T., Merlivat, L., Millero, F. J., Monteiro, P. M. S., Munro, D. R., Murata, A., Newberger, T., Omar, A. M., Ono, T., Paterson, K., Pearce, D., Pierrot, D., Robbins, L. L., Saito, S., Salisbury, J., Schlitzer, R., Schneider, B., Schweitzer, R., Sieger, R., Skjelvan, I., Sullivan, K. F., Sutherland, S. C., Sutton, A. J., Tadokoro, K., Telszewski, M., Tuma, M., van Heuven, S. M. A. C., Vandemark, D., Ward, B., Watson, A. J., and Xu, S. (2016). A multi-decade record of high-quality fCO2 data in version 3 of the Surface Ocean CO2 Atlas (SOCAT), Earth Syst. Sci. Data, 8, 383–413, https://doi.org/10.5194/essd-8-383-2016. | F2: Bakker et al. (2016) | G2: https://doi.org/10.5194/essd-8-383-2016 | H2: https://socat.info/wp-content/uploads/2017/06/cropped-socat_cat.png | I2: https://socat.info/ | K2: continuous | L2: 1957 - 2025 | M2: Open ocean, Coastal ocean, Surface | N2: Continuous | O2: The largest collection of surface ocean carbon observations | P2: The Surface Ocean CO2 Atlas features surface fCO2 measurements from both the open ocean and the coastal ocean, predominantly sourced from research vessels, ships of opportunity, and autonomous platforms including fixed moorings and uncrewed surface vehicles (USVs) (Bakker et al., 2016). It represents the most extensive collection of observational ocean CO2 data for the global surface ocean. Since 2013, SOCAT has been updated annually. Dataset flags indicate the estimated uncertainty and completeness of metadata in SOCAT synthesis products. The SOCAT gridded product contains fCO2 values with an estimated uncertainty of less than 5 µatm. | Q2: =getStatusCode(G2) -> 200 | R2: =getStatusCode(I2) -> 200
A3: 45962.863 | C3: Data compilations | D3: LDEO Surface pCO2 Database | E3: Takahashi, T., Sutherland, S. C., Wanninkhof, R., Sweeney, C., Feely, R. A., Chipman, D. W., Hales, B., Friederich, G., Chavez, F., Sabine, C., Watson, A., Bakker, D. C. E., Schuster, U., Metzl, N., Yoshikawa-Inoue, H., Ishii, M., Midorikawa, T., Nojiri, Y., Körtzinger, A., Steinhoff, T., and de Baar, H. J. W.: Climatological mean and decadal change in Surface Ocean pCO2, and net sea–air CO2 flux over the Global Oceans, Deep Sea Research Part II: Topical Studies in Oceanography, 56(8–10), 554–577, https://doi.org/10.1016/j.dsr2.2008.12.009, 2009. | F3: Takahashi et a. (2009) | G3: https://doi.org/10.1016/j.dsr2.2008.12.009 | H3: https://www.ncei.noaa.gov/access/ocean-carbon-acidification-data-system/oceans/LDEO_Underway_Database/LDEOv2019_map.jpg | I3: https://www.ncei.noaa.gov/data/oceans/ncei/ocads/metadata/0160492.html | K3: continuous | M3: Open ocean, Surface | N3: Continuous | O3: The LDEO database reports pCO2 exclusively from equilibrator-CO2 analyzer systems | P3: Dr. Taro Takahashi [LDEO, Palisades, New York] started synthesizing global surface ocean CO2 data in 1997, compiling three decades of observations (~250,000 measurements) to create inaugural monthly global surface pCO2 maps (Takahashi et al., 1997; Takahashi et al., 2002). The most recent version (V2019) expanded this dataset to approximately 14.2 million surface water pCO2 measurements spanning from 1957–2019. Distinct from the SOCAT database, the LDEO database reports pCO2, instead of fCO2, exclusively from equilibrator-CO2 analyzer systems, with an average estimated uncertainty of ± 2.5 µatm. The database is also interpolated onto a global surface ocean 4° × 5° grid for a reference year 2000 (Takahashi et al., 2009) and 2010 (Fay et al., 2024). | Q3: =getStatusCode(G3) -> 403 | R3: =getStatusCode(I3) -> 200
A4: 45961.948 | C4: Data compilations | D4: GLODAPv2 | E4: Lauvset, S. K., Lange, N., Tanhua, T., Bittig, H. C., Olsen, A., Kozyr, A., Álvarez, M., Azetsu-Scott, K., Brown, P. J., Carter, B. R., Cotrim da Cunha, L., Hoppema, M., Humphreys, M. P., Ishii, M., Jeansson, E., Murata, A., Müller, J. D., Pérez, F. F., Schirnick, C., Steinfeldt, R., Suzuki, T., Ulfsbo, A., Velo, A., Woosley, R. J., and Key, R. M.: The annual update GLODAPv2.2023: the global interior ocean biogeochemical data product, Earth Syst. Sci. Data, 16, 2047–2072, https://doi.org/10.5194/essd-16-2047-2024, 2024 | F4: Lauvset et al. (2024) | G4: https://doi.org/10.5194/essd-16-2047-2024 | H4: https://glodap.info/wp-content/uploads/2017/09/cropped-glodap_logo_trans.png | I4: https://glodap.info/ | K4: discrete | L4: 1960 - 2024 | M4: Open ocean, Water column | N4: Discrete bottle | O4: Adjustments are applied by comparing data in the deep ocean (>2000 m) using a crossover and inversion method as described by Johnson et al. (2001). | P4: The Global Ocean Data Analysis Project Version 2 (GLODAPv2) aggregates biogeochemical data collected from discrete bottle samples, offering extensive global coverage from the surface to depths (Key et al., 2015; Olsen et al., 2016; Lauvset et al., 2024). While GLODAP is primarily a product for basin-scale hydrographic data, it also includes coastal datasets and observations from a few time-series. The GLODAPv2 data product provides rigorously quality-controlled measurements for 14 essential oceanographic variables: temperature, salinity, dissolved oxygen (DO), nitrate, silicate, phosphate, DIC, TA, pH, chlorofluorocarbons (CFC-11, CFC-12, CFC-113), carbon tetrachloride (CCl4), and sulfur hexafluoride (SF6). These variables, excluding temperature, undergo both primary and secondary quality control procedures to detect outliers and adjust for significant measurement biases. GLODAPv2 was first published in 2016 and was updated annually through a living data process in Earth System Science Data from 2019 through “v2023,” which was published in 2024. For these updates, new data (including historical data not previously included in the data product) are quality controlled and adjusted to the 2016 version (Olsen et al., 2019; Olsen et al., 2020; Lauvset et al., 2021; Lauvset et al., 2022; Lauvset et al., 2024). Since the global repeat hydrography programs operate with decadal repetitions, the aim is to produce a completely new version of GLODAP, where all cruise datasets will be reevaluated, every decade. Release of the GLODAPv3 data product is planned for 2026, and is expected to evolve the secondary data quality control practices relative to those used in GLODAPv2. For more information on the secondary quality control process, refer to Tanhua et al. (2010) and Lauvset and Tanhua (2015). GLODAPv2 offers two kind of products: the collection of quality controlled data from discrete bottle samples taken at sampling location (Key et al., 2015; Olsen et al., 2016; Olsen et al., 2019; Olsen et al., 2020; Lauvset et al., 2021; Lauvset et al., 2022; Lauvset et al., 2024), and a gridded product, interpolated to a 1° × 1° grid and the 33 standard depth levels of World Ocean Atlas (WOA) (Lauvset et al., 2016). | Q4: =getStatusCode(G4) -> 200 | R4: =getStatusCode(I4) -> 200
A5: 45973.973 | B5: jswift@ucsd.edu | C5: Data compilations | D5: Quality Edited Hydrographic Data | E5: Swift, James H. and Barna, A. (2026). Quality Edited Vertical Ocean Section and Gridded Hydrographic Data. UC San Diego Library Digital Collections. Dataset. https://doi.org/10.6075/J0K074P0 | F5: Swift et al. (2026) | G5: n/a | H5: https://i.ibb.co/Q7YZfHK2/Swift-Vertical-Section-Map.png | I5: https://joa.ucsd.edu/Data_homepage | K5: irregular | L5: 1967-2025 | M5: Open ocean, Water column | N5: Discrete bottle | O5: Similar to GLODAPv2, with no adjustments | P5: Similar to GLODAPv2, with no adjustments | Q5: =getStatusCode(G5) -> #ERROR! | R5: =getStatusCode(I5) -> 404
A6: 45962.719 | C6: Data compilations | D6: World Ocean Database | E6: Mishonov, A. V., Boyer, T. P., Baranova, O. K., Bouchard, C. N., Cross, S. L., Garcia H. E., Locarnini, R. A., Paver, C. R., Wang, Z., Seidov, D., Grodsky, A. I., Beauchamp, J. G.: World Ocean Database 2023, C. Bouchard, Technical Ed., NOAA Atlas NESDIS 97, 206 pp., https://doi.org/10.25923/z885-h264, 2024. | F6: Mishonov et al. (2024) | G6: https://doi.org/10.25923/z885-h264 | H6: https://www.ncei.noaa.gov/sites/g/files/anmtlf171/files/inline-images/World%20Ocean%20Atlas%202023%20Climatology%2C%20Decade%202015-2022.png | I6: https://www.ncei.noaa.gov/products/world-ocean-database | K6: discrete | M6: Open ocean, Water column | N6: Discrete bottle | O6: Similar to GLODAPv2, with no adjustments | P6: In addition to the GLODAPv2 and JOA Suite, users can also access historical and recent original biogeochemical data collected from discrete bottle samples in a uniform format and units, along with their originator quality control (QC) flags, through the World Ocean Database (WOD) (Mishonov et al., 2024). Like the JOA Suite, these measured data remain unaltered. The WOD allows users to filter and subset data with specific variables, platforms, institutions, projects, regions, or time periods (Garcia et al., 2024). Users can visualize sampling locations on a “distribution plot” and access a cruise list for all selected data and variables. Users also have the option of exporting data in NetCDF or Comma-Separated Values (CSV) formats. Additionally, all data in the WOD are reproducible and traceable to their original data sources archived at NOAA’s National Centers for Environmental Information (NCEI). | Q6: =getStatusCode(G6) -> 200 | R6: =getStatusCode(I6) -> 200
A7: 45964.649 | C7: Data compilations | D7: SNAPO-CO2 | E7: Metzl, N., Fin, J., Lo Monaco, C., Mignon, C., Alliouane, S., Antoine, D., Bourdin, G., Boutin, J., Bozec, Y., Conan, P., Coppola, L., Diaz, F., Douville, E., Durrieu de Madron, X., Gattuso, J.-P., Gazeau, F., Golbol, M., Lansard, B., Lefèvre, D., Lefèvre, N., Lombard, F., Louanchi, F., Merlivat, L., Olivier, L., Petrenko, A., Petton, S., Pujo-Pay, M., Rabouille, C., Reverdin, G., Ridame, C., Tribollet, A., Vellucci, V., Wagener, T., and Wimart-Rousseau, C.: A synthesis of ocean total alkalinity and dissolved inorganic carbon measurements from 1993 to 2022: the SNAPO-CO2-v1 dataset, Earth Syst. Sci. Data, 16, 89–120, https://doi.org/10.5194/essd-16-89-2024, 2024. | F7: Metzl et al (2024) | G7: https://doi.org/10.5194/essd-16-89-2024 | H7: https://www.seanoe.org/data/00911/102337/illustration.gif | I7: https://doi.org/10.17882/102337 | K7: discrete | L7: 1993-2022 | M7: Open ocean, Coastal ocean, Surface, Water column | N7: Discrete bottle | O7: A compilation of cruises from multiple French initiatives | P7: Synthesis of 44,400 measurements of DIC and TA from a series of research cruises and ships of opportunity across various oceanic regions from 1993-2022, from several French research programs, to create a product called “Service National d’Analyse des Paramètres Océaniques du CO2 (SNAPO-CO2)”. | Q7: =getStatusCode(G7) -> 200 | R7: =getStatusCode(I7) -> 200
A8: 45962.038 | B8: Liqing.Jiang@noaa.gov | C8: Data compilations | D8: CODAP-NA | E8: Jiang, L.-Q., Feely, R. A., Wanninkhof, R., Greeley, D., Barbero, L., Alin, S., Carter, B. R., Pierrot, D., Featherstone, C., Hooper, J., Melrose, C., Monacci, N., Sharp, J. D., Shellito, S., Xu, Y.-Y., Kozyr, A., Byrne, R. H., Cai, W.-J., Cross, J., Johnson, G. C., Hales, B., Langdon, C., Mathis, J., Salisbury, J., and Townsend, D. W.: Coastal Ocean Data Analysis Product in North America (CODAP-NA) – an internally consistent data product for discrete inorganic carbon, oxygen, and nutrients on the North American ocean margins, Earth Syst. Sci. Data, 13, 2777–2799, https://doi.org/10.5194/essd-13-2777-2021, 2021. | F8: Jiang et al. (2021) | G8: https://doi.org/10.5194/essd-13-2777-2021 | H8: https://essd.copernicus.org/articles/13/2777/2021/essd-13-2777-2021-f01-web.png | I8: https://www.ncei.noaa.gov/data/oceans/ncei/ocads/metadata/0219960.html | K8: discrete | L8: 2003 - 2018 | M8: Coastal ocean, Water column | N8: Discrete bottle | O8: A discrete bottle based data product similar to GLODAPv2, but for the North American coastal ocean | P8: Jiang et al. (2021) synthesized two decades of discrete measurements of carbonate system variables, DO, and nutrient data from the North American continental shelves to generate the first version of Coastal Ocean Data Analysis Data Product in North America (CODAP-NA). The 2021 release encompasses 3,391 oceanographic profiles from 61 research cruises spanning the North American continental shelves from Alaska to Mexico in the west and from Canada to the Caribbean in the east. It includes 14 key variables, including temperature, salinity, DO, DIC, TA, pH, carbonate ion, fCO2, silicate, phosphate, nitrate. | Q8: =getStatusCode(G8) -> 200 | R8: =getStatusCode(I8) -> 200
A9: 46031.742 | B9: liqing.jiang@noaa.gov | C9: Data compilations | D9: AZMP Carbon | E9: Gibb, O., Cyr, F., Azetsu-Scott, K., Chassé, J., Childs, D., Gabriel, C.-E., Galbraith, P. S., Maillet, G., Pepin, P., Punshon, S., and Starr, M.: Spatiotemporal variability in pH and carbonate parameters on the Canadian Atlantic continental shelf between 2014 and 2022, Earth Syst. Sci. Data, 15, 4127–4162, https://doi.org/10.5194/essd-15-4127-2023, 2023. | F9: Gibb et al. (2023) | G9: https://doi.org/10.5194/essd-15-4127-2023 | H9: https://essd.copernicus.org/articles/15/4127/2023/essd-15-4127-2023-avatar-web.png | I9: https://doi.org/10.20383/102.0673 | K9: irregular | M9: Coastal ocean, Water column | N9: Discrete bottle | O9: A compilation of cruises from the Atlantic Zone Monitoring Program (AZMP) since 2014 | P9: Gibb et al. (2023) compiled ocean carbonate system variables data from the Canadian Atlantic Zone Monitoring Program (AZMP Carbon) since 2014. More than 100 seagoing missions are represented in this dataset. The sampling strategy generally corresponds to full-depth water samples mostly collected along standardized hydrographic sections. Implemented in 1998, the AZMP aims to characterize and understand the causes of oceanic variability at the seasonal, interannual and decadal scales in support of, among other things, fisheries management in the Atlantic Zone (including the Gulf of St. Lawrence, the Scotian shelf and the Newfoundland and Labrador shelf). Since 2014, a minimum of two of the three following carbonate system variables, DIC, TA, and pH, are also acquired by the program at standardized hydrographic stations across the zone (sampled up to three times a year). Each measurement is completed with corresponding temperature, salinity and, when available, nutrients and DO concentration data. | Q9: =getStatusCode(G9) -> 200 | R9: =getStatusCode(I9) -> 200
A10: 46004.052 | B10: egkennedy@alaska.edu | C10: Data compilations | D10: MOCHA | E10: Kennedy, E. G., Zulian, M., Hamilton, S. L., Hill, T. M., Delgado, M., Fish, C. R., Gaylord, B., Kroeker, K. J., Palmer, H. M., Ricart, A. M., Sanford, E., Spalding, A. K., Ward, M., Carrasco, G., Elliott, M., Grisby, G. V., Harris, E., Jahncke, J., Rocheleau, C. N., Westering, S., and Wilmot, M. I.: A high-resolution synthesis dataset for multistressor analyses along the US West Coast, Earth Syst. Sci. Data, 16, 219-243, https://doi.org/10.5194/essd-16-219-2024, 2024. | F10: Kennedy et al., 2023 | G10: https://doi.org/10.25921/2vve-fh39 | H10: https://i.ibb.co/XrpxsXPX/data-locs-composite-bs.png | I10: https://www.ncei.noaa.gov/access/metadata/landing-page/bin/iso?id=gov.noaa.nodc:0277984 | K10: irregular, daily | L10: 1949-2022 | M10: Regional, Coastal ocean, Surface, Water column | N10: Continuous, Discrete bottle | O10: A compilation of cruises, autonomous sensors, and shore observations for the U.S. West Coast. | P10: MOCHA compiles temperature, salinity, DO, ocean carbonate system variables (DIC, TA, pH, pCO2 , fCO2 ), nutrients, and chlorophyll observations from the full water column along the U.S. west coast. This synthesis brings together 71 different sources, including high-resolution autonomous sensors, synoptic oceanographic cruises, and shoreline samples, into a single quality-controlled product that facilitates linking nearshore, high-resolution observations to broader oceanographic conditions. MOCHA spans from the shoreline to well-beyond the continental shelf and includes over 15 million observations. The MOCHA synthesis is also available as a "daily aggregated" dataset, with all data sources averaged by day, location, and depth. | Q10: =getStatusCode(G10) -> 200 | R10: =getStatusCode(I10) -> 200
A11: 45968.793 | B11: avelo@iim.csic.es | C11: Data compilations | D11: ARIOS | E11: Padin, X.A., Velo, A., Pérez, F.F., 2020. ARIOS: a database for ocean acidification assessment in the Iberian upwelling system (1976–2018). Earth Syst. Sci. Data 12, 2647–2663. https://doi.org/10.5194/essd-12-2647-2020 | F11: Padin et al. (2020) | G11: https://doi.org/10.5194/essd-12-2647-2020 | H11: https://essd.copernicus.org/articles/12/2647/2020/essd-12-2647-2020-f01-web.png | I11: https://doi.org/10.20350/digitalCSIC/12498 | K11: irregular, discrete | L11: 1976-2018 | M11: Coastal ocean, Surface, Water column, Regional | N11: Discrete bottle | O11: 17,653 samples from 3,343 stations measuring pH, alkalinity, and biogeochemical params off NW Iberian Peninsula (1976-2018). Data primarily from Ría de Vigo, spanning Bay of Biscay to Portuguese coast | P11: A data product of 17 653 discrete samples from 3343 oceanographic stations combining measurements of pH, alkalinity and other biogeochemical parameters off the northwestern Iberian Peninsula from June 1976 to September 2018 is presented in this study. The oceanography cruises funded by 24 projects were primarily carried out in the Ría de Vigo coastal inlet but also in an area ranging from the Bay of Biscay to the Portuguese coast. The robust seasonal cycles and long-term trends were only calculated along a longitudinal section, gathering data from the coastal and oceanic zone of the Iberian upwelling system. The pH in the surface waters of these separated regions, which were highly variable due to intense photosynthesis and the remineralization of organic matter, showed an interannual acidification ranging from −0.0012 to −0.0039 yr−1 that grew towards the coastline. This result is obtained despite the buffering capacity increasing in the coastal waters further inland as shown by the increase in alkalinity by 1.1±0.7 and 2.6±1.0 µmol kg−1 yr−1 in the inner and outer Ría de Vigo respectively, driven by interannual changes in the surface salinity of 0.0193±0.0056 and 0.0426±0.016 psu yr−1 respectively. The loss of the vertical salinity gradient in the long-term trend in the inner ria was consistent with other significant biogeochemical changes such as a lower oxygen concentration and fertilization of the surface waters. These findings seem to be related to a growing footprint of sediment remineralization of organic matter in the surface layer of a more homogeneous water column. | Q11: =getStatusCode(G11) -> 200 | R11: =getStatusCode(I11) -> 200
A12: 45964.778 | C12: Data compilations | D12: Marine Inorganic Carbonate Chemistry in the Northern Gulf of Alaska | E12: Monacci, N. M., Cross, J. N., Evans, W., Mathis, J. T., and Wang, H.: A decade of marine inorganic carbon chemistry observations in the northern Gulf of Alaska – insights into an environment in transition, Earth Syst. Sci. Data, 16, 647–665, https://doi.org/10.5194/essd-16-647-2024, 2024. | F12: Monacci et al. (2024) | G12: https://doi.org/10.5194/essd-16-647-2024 | H12: https://essd.copernicus.org/articles/16/647/2024/essd-16-647-2024-avatar-web.png | I12: https://www.ncei.noaa.gov/data/oceans/ncei/ocads/metadata/0277034.html | K12: discrete | L12: 2008 - 2017 | M12: Coastal ocean, Water column | N12: Discrete bottle | O12: A synthesis of twenty cruises from 2008 to 2017 on the Gulf of Alaska (GAK) Line | P12: Monacci et al. (2023) compiled a data product of discrete seawater samples collected each May and September over a 10-year period from 2008 to 2017 along the long-term hydrographic line in the Gulf of Alaska (GAK Line). Samples were collected from a sampling rosette on a profiling CTD. Data variables include profiled seawater temperature, salinity, and DO. Discrete sample variables include DO (i.e., Winkler titrations), macronutrients (nitrate, nitrite, phosphate, silicic acid), DIC, and TA. All carbonate system variables were analyzed at the Ocean Acidification Research Center (OARC) at the University of Alaska Fairbanks (UAF). The repeat hydrographic cruises were funded by the Alaska Ocean Observing System (AOOS), the Exxon Valdez Oil Spill Trustee Council (EVOS), Gulf Watch Alaska, and the North Pacific Research Board (NPRB) and were mostly conducted aboard the United States Fish and Wildlife Service (USFWS) R/V Tiĝlax̂. | Q12: =getStatusCode(G12) -> 200 | R12: =getStatusCode(I12) -> 200
A13: 45987.642 | B13: nicole.besemer@noaa.gov | C13: Data compilations | D13: Coral Reef Carbonate Chemistry Off the Florida Keys | E13: Palacio-Castro, A. M., Enochs, I. C., Besemer, N., Boyd, A., Jankulak, M., Kolodziej, G., et al. (2023). Coral reef carbonate chemistry reveals interannual, seasonal, and spatial impacts on ocean acidification off Florida. Global Biogeochemical Cycles, 37, e2023GB007789. https://doi.org/10.1029/2023GB007789 | F13: Palacio-Castro et al. (2023) | G13: https://doi.org/10.1029/2023GB007789 | H13: https://i.ibb.co/yc5J25Q6/gbc21508-fig-0001-m.jpg | I13: https://www.ncei.noaa.gov/access/metadata/landing-page/bin/iso?id=gov.noaa.nodc:NCRMP-CO3-Atlantic | K13: irregular, bi-monthly | M13: Regional, Coastal ocean, Surface | N13: Discrete bottle | O13: Temporal trends of DIC, TA, pCO2, pH, Ωarag, in different areas of the Florida Keys | P13: Analysis of discrete seawater samples compiled from 38 permanent stations located along 10 inshore-offshore transects at the Florida Coral Reef. These samples were collected as part of NOAA's National Coral Reef Monitoring Program (NCRMP) and the South Florida Ecosystem Restoration Research (SFER) cruises. The time-series analysis provides insight into the dynamic carbonate conditions spanning the inshore to offshore gradients, encompassing four distinct regions of the Florida Coral Reef: Biscayne Bay, the Upper Keys, Middle Keys, and Lower Keys. | Q13: =getStatusCode(G13) -> 403 | R13: =getStatusCode(I13) -> 200
A14: 45979.717 | B14: simone.r.alin@noaa.gov, janewton@uw.edu | C14: Data compilations | D14: Salish Cruise Data Package | E14: Alin, S.R., J.A. Newton, R.A. Feely, B. Curry, D. Greeley, J. Herndon, and M. Warner (2024a). A decade-long cruise time-series (2008–2018) of physical and biogeochemical conditions in the southern Salish Sea, North America. Earth System Science Data, 16, 837–865, https://doi.org/10.5194/essd-16-837-2024 | F14: Alin et al. (2025a) | G14: https://doi.org/10.5194/essd-16-837-2024 | H14: https://essd.copernicus.org/articles/16/837/2024/essd-16-837-2024-avatar-web.png | I14: https://www.ncei.noaa.gov/access/ocean-carbon-acidification-data-system/oceans/SalishCruise_DataPackage.html | K14: seasonal, discrete, continuous | L14: 2008–2024 | M14: Coastal ocean, Estuaries, Water column | N14: Discrete bottle, Continuous | O14: A QCed compilation of cruise datasets from 2008 to 2024 in the southern Salish Sea and northern Washington coast. | P14: Alin et al. (2025a) compiled data from 61 individual cruise data sets that sampled marine waters of the southern Salish Sea and northern Washington coast (United States) from 2008 to 2024. Ongoing seasonal sampling occurred during April, July, and September for Puget Sound cruises has occurred since 2014 and most frequently during May and October for Sound-to-Sea cruises, which sample from Puget Sound through the Strait of Juan de Fuca to the northern Washington coast. The Salish cruise data package contains observations from a oceanographic water column profiles, with CTD sensor measurements of temperature, salinity, and oxygen; as well as discrete measurements of oxygen, nutrient, and inorganic carbonate content. | Q14: =getStatusCode(G14) -> 200 | R14: =getStatusCode(I14) -> 200
A15: 45979.717 | B15: simone.r.alin@noaa.gov, janewton@uw.edu | C15: Data compilations | D15: Salish Cruise Multi-stressor Data Product | E15: Alin, S.R., J.A. Newton, R.A. Feely, S. Siedlecki, and D. Greeley (2024b). Seasonality and response of ocean acidification and hypoxia to major environmental anomalies in the southern Salish Sea, North America (2014–2018). Biogeosciences, 21, 1639–1673, https://doi.org/10.5194/bg-21-1639-2024 | F15: Alin et al. (2025b) | G15: https://doi.org/10.5194/bg-21-1639-2024 | H15: https://bg.copernicus.org/articles/21/1639/2024/bg-21-1639-2024-avatar-web.png | I15: https://www.ncei.noaa.gov/access/ocean-carbon-acidification-data-system/oceans/SalishCruises_DataProduct.html | K15: seasonal, discrete, continuous | L15: 2008–2024 | M15: Coastal ocean, Estuaries, Water column | N15: Discrete bottle, Continuous | O15: A multi-stressor (ocean acidification, hypoxia, marine heatwaves) data product based on cruises from 2008 to 2024 in the southern Salish Sea and northern Washington coast (USA). | P15: Alin et al. (2025b) provides a data product including all finalized records from the Salish cruise data package that had a complete suite of measurements for CTD temperature, salinity, and oxygen, as well as discrete measurements of oxygen, nutrients, dissolved inorganic carbon, and total akalinity. This product also provides the most commonly used calculated carbonate system variables--pH (on the total scale), carbon dioxide fugacity (fCO2) and partial , Ωarag, and Ωcalc--to facilitate their use by a broader group of end users. | Q15: =getStatusCode(G15) -> 200 | R15: =getStatusCode(I15) -> 200
A16: 45967.509 | B16: ana.franco@bsc.es | C16: Data compilations | D16: Line P Marine Carbonate Chemistry Compilation | E16: Franco, A. C., Ianson, D., Ross, T., Hamme, R. C., Monahan, A. H., Christian, J. R., Davelaar, M., Johnson, W. K., Miller, L. A., Robert, M., and Tortell, P. D. 2021. Anthropogenic and climatic contributions to observed carbon system trends in the northeast Pacific. Global Biogeochemical Cycles, 35(7). https://doi.org/10.1029/2020GB006829 | F16: Franco et al., (2021) | G16: https://doi.org/10.1029/2020GB006829 | H16: https://i.ibb.co/4wb5JLp1/fig1-map-francoetal2021.png | I16: https://www.ncei.noaa.gov/data/oceans/ncei/ocads/metadata/0234342.html | K16: irregular, sub-annual, discrete | L16: 1990 - 2019 | M16: Open ocean, Water column, Regional | N16: Discrete bottle | O16: A compilation of fifty-five Line P cruises containing discrete DIC and TA profiles at five stations in the Northeast Pacific Ocean. Sampled approximately three times per year from 1990 to 2019 | P16: This dataset contains marine carbonate system measurements collected during 55 Line P cruises from 1990 to 2019 in the subarctic Northeast Pacific. The dataset contains quality-controlled, discrete profiles of dissolved inorganic carbon (DIC), total alkalinity (TA), temperature, salinity, dissolved oxygen and nutrients. From a total of 27 hydrographic time-series stations, only the five major stations where DIC and TA are routinely sampled were included in this compilation. Cruises were conducted approximately three times per year, typically in February, May/June and August/September. Each vertical profile was individually inspected and contrasted with the whole pool of data relative to salinity, density, and oxygen to detect and flag poor quality data following the World Ocean Circulation Experiment (WOCE) quality control convention. The recommended cruise-specific adjustments from the Pacific Ocean Interior Carbon (PACIFICA) data synthesis were applied. The Line P carbonate chemistry timeseries is maintained by Fisheries and Oceans Canada and continues to the present day. Data are available and continuously updated in the Line P repository, which can be publicly accessed after generating an account at https://waterproperties.ca. | Q16: =getStatusCode(G16) -> 403 | R16: =getStatusCode(I16) -> 200
A17: 45973.935 | B17: jens.terhaar@unibe.ch | C17: Data compilations | D17: Anthropogenic Carbon in the Arctic Ocean | E17: Terhaar, J., Tanhua, T., Stöven, T., Orr, J. C., and Bopp, L.: Evaluation of data‐based estimates of anthropogenic carbon in the Arctic Ocean, Journal of Geophysical Research: Oceans, 125(6), https://doi.org/10.1029/2020jc016124, 2020. | F17: Terhaar et al. (2020) | G17: https://doi.org/10.1029/2020jc016124 | H17: https://www.seanoe.org/data/00927/103920/illustration.gif | I17: https://www.seanoe.org/data/00927/103920/ | K17: climatology | L17: 2005 | M17: Open ocean | N17: Discrete bottle | O17: Observation-based estimates of anthropogenic carbon in the Arctic Ocean | P17: This dataset includes anthropogenic carbon estimates in the Arctic Ocean based on measurements of transient tracers, such as CFC-12 and SF6 (Terhaar et al., 2020; Tanhua et al., 2009). Using the transient time distribution (TTD) method, anthropogenic carbon estimates were estimated at measurement locations across all basins of the Arctic Ocean between 1983 and 2005. In addition to these estimates, adjusted estimates of anthropogenic carbon at these locations are provided to account for differences in the saturation of transient tracers and anthropogenic carbon in Arctic Ocean surface waters that caused anthropogenic carbon estimates to be biased low (Terhaar et al., 2020). It is recommended to use the adjusted estimates. This dataset can be accessed at https://doi.org/10.17882/103920 (Terhaar et al., 2024). | Q17: =getStatusCode(G17) -> 403 | R17: =getStatusCode(I17) -> 200
A18: 45975.472 | B18: nick.bates@bios.edu | C18: Time series | D18: BATS | E18: Bates, N., Johnson, R. J., Lomas, M. W., Smith, D., Lethaby, P. J., Bakker, R., Davey, E., Derbyshire, L., Enright, M., Garley, R., Hayden, M. G., Lomas, D., May, R., Medley, C., Stuart, E., Chambers, E. (2025) Discrete bottle samples collected at the Bermuda Atlantic Time-series Study (BATS) site in the Sargasso Sea from October 1988 through December 2024. Biological and Chemical Oceanography Data Management Office (BCO-DMO). (Version 8) Version Date 2025-06-27 [if applicable, indicate subset used]. doi:10.26008/1912/bco-dmo.3782.8 [access date];</br></br>Bates, N., and Johnson, R.J., 2023. Forty years of ocean acidification observations (1983-2023) in the Sargasso Sea at the Bermuda Atlantic Time-series Study (BATS) site. Frontiers in Marine Science, 10, https://doi.org/10.3389/fmars.2023.1289931. | F18: Bates and Johnson (2023) | G18: https://doi.org/10.3389/fmars.2023.1289931 | H18: https://www.frontiersin.org/files/Articles/1289931/fmars-10-1289931-HTML-r1/image_m/fmars-10-1289931-g001.jpg | I18: https://www.bco-dmo.org/project/2124 | K18: monthly | L18: 1988-2025 | M18: Open ocean | N18: Discrete bottle | O18: Forty years of ocean acidification observations (1983-2023) in the Sargasso Sea at the Bermuda Atlantic Time-series Study (BATS) site. | P18: Ocean physical and biogeochemical conditions are rapidly changing over time. Forty years of observations from 1983 to 2023 collected at the Bermuda Atlantic Time-series Study (BATS) site near Bermuda in the North Atlantic Ocean shows continuing trends of surface warming, increase in salinity, loss of dissolved oxygen (DO), increase in carbon dioxide (CO2), and ocean acidification (OA) effects. Over this period, the ocean has warmed by about +1°C, increased in salinity by +0.136, and lost DO by 12.5 µmol kg−1 or ~6%. Since the 1980s, ocean dissolved inorganic carbon (DIC), total alkalinity (TA), a tracer of anthropogenic CO2 (CTrOCA), and fugacities/partial pressures of CO2 (i.e., fCO2 and pCO2) have continued to increase substantially, with no evidence of a reduction in the rates of change over time. Contemporaneously, ocean pH has decreased by ~0.1 pH units [with ocean acidity (i.e., H+) increasing by >30%], and the saturation states of calcium carbonate minerals (Ωcalcite and Ωaragonite) have decreased. These OA indicators show that the chemical conditions for calcification have become less favorable over the past 40 years. Updating of data and trends at the BATS site show how ocean chemistry of the 2020s is now outside the range observed in the 1980s, and how essential these data are for predicting the response of ocean chemistry and marine ecosystems to future shifting earth and ocean conditions. | Q18: =getStatusCode(G18) -> 200 | R18: =getStatusCode(I18) -> 200
A19: 45977.154 | B19: jdore@montana.edu | C19: Time series | D19: HOT | E19: Dore, J. E., Lukas, R., Sadler, D. W., Church, M. J., and Karl, D. M.: Physical and biogeochemical modulation of ocean acidification in the central North Pacific, Proc. Natl. Acad. Sci., 106, 12235-12240, https://doi.org/10.1073/pnas.0906044106, 2009. | F19: Dore et al. (2009) | G19: https://doi.org/10.1073/pnas.0906044106 | H19: https://i.ibb.co/B2vPqjyw/HOTlogo.jpg | I19: https://doi.org/10.1575/1912/bco-dmo.3773.1 | K19: monthly | L19: 1988-2025 | M19: Open ocean, Water column | N19: Continuous, Discrete bottle | O19: 35+ years of inorganic carbon dynamics in the open waters of the central North Pacific | P19: The Hawaii Ocean Time-series (HOT) CO2 measurement program documents 35+ years of inorganic carbon dynamics in the open waters of the central North Pacific. Since October 1988, full ocean depth profiles of DIC and TA have been analyzed, and direct measurements of pH have been made over most of this longest-running Pacific Ocean time-series study. The program is based on shipboard observations and experiments conducted on ~10 expeditions per annum to Station ALOHA (22.75°N, 158°W). | Q19: =getStatusCode(G19) -> 200 | R19: =getStatusCode(I19) -> 403
A20: 46032.028 | B20: Liqing.Jiang@noaa.gov | C20: Time series | D20: ESTOC | E20: González-Dávila, M. and Santana-Casiano J. M.: Long-term trends of pH and inorganic carbon in the Eastern North Atlantic: the ESTOC site, Front. Mar. Sci., 10, 1236214, https://doi.org/10.3389/fmars.2023.1236214, 2023. | F20: González-Dávila and Santana-Casiano (2023) | G20: https://doi.org/10.3389/fmars.2023.1236214 | H20: https://www.frontiersin.org/files/Articles/1236214/fmars-10-1236214-HTML-r1/image_m/fmars-10-1236214-g001.jpg | I20: https://doi.org/10.1594/PANGAEA.959856 | K20: irregular | M20: Open ocean | N20: Continuous, Discrete bottle | O20: The longest continuous monthly record of warming, rising carbon dioxide levels, and OA in the eastern North Atlantic | P20: The European Station for Time-series in the Ocean (ESTOC) began carbon dioxide monitoring in October 1995, providing a 30-year record on DIC, TA, and pH. This dataset represents the longest continuous monthly record of warming, rising carbon dioxide levels, and acidification in the eastern North Atlantic (González-Dávila and Santana-Casiano, 2023). ESTOC is located 100 km north of the Canary Islands archipelago (https://plocan.eu/en/installations/ocean-observatory). The program includes a ship-based observation system, measuring physical, chemical, and biological variables throughout the 3,670-meter water column. It also features a moored platform for surface meteorological and oceanic observations as well as subsurface measurements, maintained by the Canary Island Oceanic Platform (PLOCAN, https://plocan.eu/en) and the University of Las Palmas de Gran Canaria (https://iocag.ulpgc.es/research/research-units/quima). Carbonate system measurements include full-depth bottle sampling for photometric pH, TA, and DIC, conducted monthly from 1995 to 2008, every two months until 2018, and semiannually in recent years due to limited ship time, timed to coincide with moored structure maintenance. ESTOC is also visited every two weeks by a volunteer observing ship, ES-SOOP-CanOA (https://meta.icos-cp.eu/resources/stations/OS_687B), part of the European Research Infrastructure ICOS (https://www.icos-cp.eu/observations/ocean/stations), which provides real-time surface data on carbon dioxide fluxes and OA. The program also includes the CO2-ESTOC oceanographic buoy (https://meta.icos-cp.eu/labeling/). | Q20: =getStatusCode(G20) -> 200 | R20: =getStatusCode(I20) -> 200
A21: 45965.727 | B21: liqing.jiang@noaa.gov | C21: Time series | D21: Point B Time-series | E21: Kapsenberg, L., Alliouane, S., Gazeau, F., Mousseau, L., and Gattuso, J.-P.: Coastal ocean acidification and increasing total alkalinity in the northwestern Mediterranean Sea, Ocean Sci., 13, 411–426, https://doi.org/10.5194/os-13-411-2017, 2017. | F21: Kapsenberg et al. (2017) | G21: https://doi.org/10.5194/os-13-411-2017 | H21: https://i.ibb.co/8gK4B2BP/Point-B.png | I21: https://doi.org/10.1594/PANGAEA.727120 | K21: discrete | M21: Coastal ocean | N21: Discrete bottle | O21: Carbonate chemistry at a coastal site of the Bay of Villefranche, France | P21: The Point B Time-series documents the carbonate chemistry at a coastal site of the Bay of Villefranche (43.686200N 7.314800E) in Villefranche-sur-mer, France, northwestern Mediterranean Sea. Since January 2007, seawater is sampled weekly at 1 and 50 m, and analyzed for DIC and TA. Salinity and temperature are extracted from CTD profiles. Variables of the carbonate system such as pH (total scale) are calculated using the R package seacarb. | Q21: =getStatusCode(G21) -> 200 | R21: =getStatusCode(I21) -> 200
A22: 45965.744 | B22: liqing.jiang@noaa.gov | C22: Time series | D22: Ny-Ålesund Time-series | E22: Gattuso, J.-P., Alliouane, S., and Fischer, P.: High-frequency, year-round time series of the carbonate chemistry in a high-Arctic fjord (Svalbard), Earth Syst. Sci. Data, 15, 2809–2825, https://doi.org/10.5194/essd-15-2809-2023, 2023. | F22: Gattuso et al. (2023) | G22: https://doi.org/10.5194/essd-15-2809-2023 | H22: https://essd.copernicus.org/articles/15/2809/2023/essd-15-2809-2023-avatar-web.png | I22: https://doi.org//10.1594/PANGAEA.957028 | K22: continuous, discrete | M22: Coastal ocean | N22: Continuous | O22: Carbonate chemistry at a coastal site of Kongsfjorden, Spitsbergen | P22: The Ny-Ålesund Time-series documents the carbonate chemistry at a coastal site of Kongsfjorden, Spitsbergen (78.930660N 11.920030E) during the period 2015-2021. It is the first high-frequency (1 hour), multi-year (6 years) dataset of salinity, temperature, pCO2, pH, as well as calculated DIC and TA in the High-Arctic Ocean (Gattuso et al., 2023). | Q22: =getStatusCode(G22) -> 200 | R22: =getStatusCode(I22) -> 200
A23: 46030.626 | B23: nlan@norceresearch.no | C23: Time series | D23: SPOTS | E23: Lange, N., Fiedler, B., Álvarez, M., Benoit-Cattin, A., Benway, H., Buttigieg, P. L., Coppola, L., Currie, K., Flecha, S., Gerlach, D. S., Honda, M., Huertas, I. E., Lauvset, S. K., Muller-Karger, F., Körtzinger, A., O'Brien, K. M., Ólafsdóttir, S. R., Pacheco, F. C., Rueda-Roa, D., Skjelvan, I., Wakita, M., White, A., and Tanhua, T.: Synthesis Product for Ocean Time Series (SPOTS) – a ship-based biogeochemical pilot, Earth Syst. Sci. Data, 16, 1901–1931, https://doi.org/10.5194/essd-16-1901-2024, 2024. | F23: Lange et al., (2024) | G23: https://doi.org/10.5194/essd-16-1901-2024 | H23: https://i.ibb.co/qYM6NNbv/Logo.png | I23: https://www.bco-dmo.org/dataset/896862 | K23: irregular | L23: 1983 - 2021 | M23: Open ocean, Coastal ocean, Water column | N23: Discrete bottle | O23: The pilot includes biogeochemical data from 12 fixed ship-based time-series programs | P23: The Synthesis Product for Ocean Time-Series (SPOTS) is a ship-based biogeochemical pilot, aiming at regularly providing high quality data from fixed time-series stations with consistent format and semantics (Lange et al., 2024a). The pilot includes data from 12 fixed ship-based time-series programs with a focus on the Global Ocean Observing System’s biogeochemical essential ocean variables. These stations represent unique marine environments across a variety of spatiotemporal resolutions and ranges, with data from 1983 to 2021. | Q23: =getStatusCode(G23) -> 200 | R23: =getStatusCode(I23) -> 200
A24: 45962.744 | C24: Time series | D24: pCO2 and pH Time-series from 40 Surface Buoys | E24: Sutton, A. J., Feely, R. A., Maenner-Jones, S., Musielwicz, S., Osborne, J., Dietrich, C., Monacci, N., Cross, J., Bott, R., Kozyr, A., Andersson, A. J., Bates, N. R., Cai, W.-J., Cronin, M. F., De Carlo, E. H., Hales, B., Howden, S. D., Lee, C. M., Manzello, D. P., McPhaden, M. J., Meléndez, M., Mickett, J. B., Newton, J. A., Noakes, S. E., Noh, J. H., Olafsdottir, S. R., Salisbury, J. E., Send, U., Trull, T. W., Vandemark, D. C., and Weller, R. A.: Autonomous seawater pCO2 and pH time series from 40 surface buoys and the emergence of anthropogenic trends, Earth Syst. Sci. Data, 11, 421–439, https://doi.org/10.5194/essd-11-421-2019, 2019. | F24: Sutton et al. (2019) | G24: https://doi.org/10.5194/essd-11-421-2019 | H24: https://essd.copernicus.org/articles/11/421/2019/essd-11-421-2019-avatar-web.png | I24: https://www.ncei.noaa.gov/access/ocean-carbon-acidification-data-system/oceans/Moorings/ndp097.html | K24: continuous | M24: Open ocean, Coastal ocean, Surface | N24: Continuous | O24: Based on 40 moored surface pCO2 time-series, with 17 of them containing pH | P24: Sutton et al. (2019) established a living dataset comprising 40 individual autonomous moored surface ocean pCO2 time-series established between 2004 and 2013, 17 of them also include autonomous pH measurements. These time-series characterize a wide range of surface ocean carbonate system conditions, across a variety of environments, including 17 oceanic and 13 coastal locations, as well as 10 coral reefs. | Q24: =getStatusCode(G24) -> 200 | R24: =getStatusCode(I24) -> 200
A25: 46121.63 | B25: sebastien.petton@ifremer.fr | C25: Time series | D25: French coastal carbonate time-series | E25: Petton, S., Pernet, F., Le Roy, V., Huber, M., Martin, S., Macé, É., Bozec, Y., Loisel, S., Rimmelin-Maury, P., Grossteffan, É., Repecaud, M., Quemener, L., Retho, M., Manac'h, S., Papin, M., Pineau, P., Lacoue-Labarthe, T., Deborde, J., Costes, L., Polsenaere, P., Rigouin, L., Benhamou, J., Gouriou, L., Lequeux, J., Labourdette, N., Savoye, N., Messiaen, G., Foucault, E., Ouisse, V., Richard, M., Lagarde, F., Voron, F., Kempf, V., Mas, S., Giannecchini, L., Vidussi, F., Mostajir, B., Leredde, Y., Alliouane, S., Gattuso, J.-P., and Gazeau, F.: French coastal network for carbonate system monitoring: the CocoriCO2 dataset, Earth Syst. Sci. Data, 16, 1667–1688, https://doi.org/10.5194/essd-16-1667-2024, 2024. | F25: Petton et al. (2022) | G25: https://doi.org/10.5194/essd-16-1667-2024 | H25: https://i.ibb.co/67Qd9xr3/Fig6-Suivi-Cocori-CO2-p-H.png | I25: https://doi.org/10.17882/96982 | K25: daily, monthly, discrete | L25: 2021 - 2025 | M25: Coastal ocean, Estuaries | N25: Continuous, Discrete bottle | O25: High-frequency pH and biweekly carbonate chemistry monitoring at six strategic shellfish production sites along the French Atlantic and Mediterranean coasts. | P25: Petton et al. (2023a) present a dataset generated by the CocoriCO2 project, launched in 2021 to monitor acidification across French coastal waters. This network relies on six strategic sites for shellfish farming (Atlantic and Mediterranean), where autonomous sensors record high-frequency pH (every 15 min) alongside biweekly monitoring of total alkalinity and dissolved inorganic carbon. Spanning over two years, these time-series reveal significant variability in the carbonate system driven by freshwater inputs, tides, and biological processes, contrasting with the relative stability of the open ocean. | Q25: =getStatusCode(G25) -> 200 | R25: =getStatusCode(I25) -> 200
A26: 45973.952 | B26: afay@ldeo.columbia.edu | C26: Gridded surface | D26: Takahashi ΔfCO2 & Flux Climatology | E26: Fay, A. R., Munro, D. R., McKinley, G. A., Pierrot, D., Sutherland, S. C., Sweeney, C., and Wanninkhof, R. 2024. Updated climatological mean ΔfCO2 and net sea–air CO2 flux over the global open ocean regions, Earth Syst. Sci. Data, 16, 2123–2139, https://doi.org/10.5194/essd-16-2123-2024. | F26: Fay et al. (2024) | G26: https://doi.org/10.5194/essd-16-2123-2024 | H26: https://essd.copernicus.org/articles/16/2123/2024/essd-16-2123-2024-avatar-web.png | I26: https://doi.org/10.25921/295g-sn13 | J26: 1° x 1° | K26: monthly | L26: 2010 | M26: Open ocean | O26: Does not use proxy variables for extrapolation. Only produced as monthly climatology. | P26: Following on previous climatologies published by the late Taro Takahashi in 1997 and 2009, Fay et al. (2024) created a legacy climatology using his methodology and the updated SOCAT database of observations. This product provides 12 months of delta fCO2 values and corresponding fluxes for a base year of 2010 at 4° × 5° resolution subsequently subgridded to 1° × 1° resolution and near-global coverage. This climatology represents the mean of ocean conditions over the last four decades and is distinctive relative to many other mechanistic machine learning approaches in that it interpolates in time and space using only the available fCO2 data and a surface water advection scheme rather than using proxy variables for gap filling. It uses the median of observations to determine a reference year of 2010 and fluxes are provided using air-sea partial pressure differences and inputs from the SeaFlux product (Fay et al., 2021). | Q26: =getStatusCode(G26) -> 200 | R26: =getStatusCode(I26) -> 200
A27: 45964.856 | C27: Gridded surface | D27: MPI-ULB-SOM-FFN | E27: Landschützer, P., Laruelle, G. G., Roobaert, A., and Regnier, P.: A uniform pCO2 climatology combining open and coastal oceans, Earth Syst. Sci. Data, 12, 2537–2553, https://doi.org/10.5194/essd-12-2537-2020, 2020. | F27: Landschützer et al. (2020) | G27: https://doi.org/10.5194/essd-12-2537-2020 | H27: https://essd.copernicus.org/articles/12/2537/2020/essd-12-2537-2020-avatar-web.png | I27: https://www.ncei.noaa.gov/access/ocean-carbon-acidification-data-system/oceans/MPI-ULB-SOM_FFN_clim.html | J27: 0.25° x 0.25° | K27: monthly, climatology | M27: Open ocean, Coastal ocean, Surface | O27: Monthly gridded pCO2 without adjusting for a specific reference year, high-resolution coastal ocean coverage. | P27: Landschützer et al. (2020a) created a uniform pCO2 climatology combining open and coastal oceans. It is a monthly gridded global surface ocean pCO2 data product without adjusting for a specific reference year. Developed on a higher-resolution 0.25° × 0.25° global surface-ocean grid, this product is the result of combining two neural network-based pCO2 products: the open ocean product described below (i.e., Landschützer et al., 2016) and the coastal product created by Laruelle et al. (2017). Consequently, it represents coastal zones better. Data collected between 1998 and 2015 from the SOCAT database (Version 5) were used to create this data product. | Q27: =getStatusCode(G27) -> 200 | R27: =getStatusCode(I27) -> 200
A28: 45964.86 | C28: Gridded surface | D28: VLIZ-SOM-FFN | E28: Landschützer, P., Gruber, N., and Bakker, D. C. E.: Decadal variations and trends of the Global Ocean Carbon Sink, Global Biogeochemical Cycles, 30(10), 1396–1417. https://doi.org/10.1002/2015gb005359, 2016. | F28: Landschützer et al. (2016) | G28: https://doi.org/10.1002/2015gb005359 | H28: https://www.ncei.noaa.gov/data/oceans/archive/arc0105/0160558/8.8/about/0160558_preview.png | I28: https://www.ncei.noaa.gov/data/oceans/ncei/ocads/metadata/0160558.html | J28: 1° x 1° | K28: monthly, climatology | L28: 1982 - 2025 | M28: Open ocean | O28: Monthly gridded pCO2 from 1982 through near present | P28: Landschützer et al. (2016) employed the Self-Organizing-Map Feed-Forward Network (SOM-FFN) neural network method (Landschützer et al., 2013) to map sea surface pCO2 from SOCAT (see No. 1 above) (Bakker et al., 2014) to generate monthly pCO2 fields on a 1° × 1° global surface ocean grid, covering the period from 1982 to near present. It is based on the gridded pCO2 measurements from SOCAT and is updated regularly. The creation of the pCO2 fields involve a two-step neural network approach, which has been extensively detailed and validated in previous works by Landschützer et al. (2013, 2014, 2016). In the initial step, the global ocean is clustered into biogeochemical provinces, and subsequently, the non-linear relationship between CO2 driver variables and gridded data from SOCAT (Bakker et al., 2016) is reconstructed. Air-sea CO2 fluxes are also computed based on the air-sea pCO2 difference, utilizing a bulk gas transfer formulation as described by Landschützer et al. (2013, 2014, 2016). | Q28: =getStatusCode(G28) -> 403 | R28: =getStatusCode(I28) -> 200
A29: 45966.249 | B29: iida-ysk@met.kishou.go.jp | C29: Gridded surface | D29: JMA-MLR | E29: Iida, Y., Takatani, Y., Kojima, A., and Ishii, M. 2021. Global trends of ocean CO2 sink and ocean acidification: An obsevation-based reconstruction of surface ocean inorganic carbon variables, J. Oceanogr. 77, 323-358, https://doi.org/10.1007/s10872-020-00571-5 | F29: Iida et al. (2021) | G29: https://doi.org/10.1007/s10872-020-00571-5 | H29: https://www.data.jma.go.jp/kaiyou/data/db/mar_env/results/co2_flux/animation/fluxmap_fig/flux_2023MN.png | I29: https://doi.org/10.1007/s10872-020-00571-5 | J29: 1° x 1° | K29: monthly | L29: 1990-2023 | M29: Open ocean, Surface | O29: Temporal trends of DIC, TA, pCO2, air-sea CO2 flux, pH, and Ωarag. | P29: Iida et al. (2021) developed a monthly data product for inorganic carbonate variables on a 1° × 1° global surface ocean grid for the period 1993?2018. Variables include DIC, TA, pCO2, sea-air CO2 flux, pH, and Ωarag. They leveraged data products such as SOCAT.v2019 (Bakker et al., 2016) and GLODAPv2.2019 (Olsen et al., 2019), as well as satellite-based variables, including sea-surface dynamic height (SSDH), mixed layer depth (MLD), and chlorophyll-a. The product is updated annually using the latest SOCAT and GLODAPv2 data. | Q29: =getStatusCode(G29) -> 200 | R29: =getStatusCode(I29) -> 200
A30: 45961.91 | B30: gregorl@ethz.ch | C30: Gridded surface | D30: OceanSODA-ETHZv1 | E30: Gregor, L.; Gruber, N. OceanSODA-ETHZ: A Global Gridded Data Set of the Surface Ocean Carbonate System for Seasonal to Decadal Studies of Ocean Acidification. Earth System Science Data 2021, 13 (2), 777–808. https://doi.org/10.5194/essd-13-777-2021. | F30: Gregor and Gruber (2021) | G30: https://doi.org/10.5194/essd-13-777-2021 | H30: https://essd.copernicus.org/articles/13/777/2021/essd-13-777-2021-avatar-web.png | I30: https://www.ncei.noaa.gov/data/oceans/ncei/ocads/metadata/0220059.html | J30: 1° x 1° | K30: monthly | L30: 1982 - 2022 | M30: Open ocean, Surface | O30: Temporal trends of DIC, TA, pCO2, pH, Ωarag, and Ωcalc | P30: A monthly gridded global surface ocean data product for multiple ocean carbonate system variables, including DIC, TA, pCO2, pH (total scale), Ωarag, and Ωcalc (Gregor and Gruber, 2020; Gregor and Gruber, 2021; Gregor and Gruber, 2023; Ma et al., 2023). This dataset is structured on a 1°×1° global surface ocean grid with monthly resolution from 1982–2022, facilitating research on OA over seasonal to decadal scales. The OceanSODA-ETHZ data product was created by extrapolating in time and space the surface ocean observations of fCO2 from SOCATv2022 (Bakker et al., 2016) and TA from GLODAPv2.2022 using the newly developed Geospatial Random Cluster Ensemble Regression (GRaCER) method (Gregor, 2021). TA and pCO2 were then used to calculate the remaining variables of the marine carbonate system with the PyCO2SYS software (Humphreys et al., 2022). Phosphate and silicate from WOA 2018 product were used (Boyer et al., 2018; Garcia et al., 2018a). | Q30: =getStatusCode(G30) -> 200 | R30: =getStatusCode(I30) -> 200
A31: 45961.913 | B31: gregorl@ethz.ch | C31: Gridded surface | D31: OceanSODA-ETHZv2 | E31: Gregor, L.; Shutler, J.; Gruber, N. High-Resolution Variability of the Ocean Carbon Sink. Global Biogeochemical Cycles 2024, 38 (8), e2024GB008127. https://doi.org/10.1029/2024GB008127. | F31: Gregor et al. (2024) | G31: https://doi.org/10.1029/2024GB008127 | H31: https://i.ibb.co/9mHfTX1H/gbc21584-fig-0007-m.jpg | I31: https://zenodo.org/records/11206366 | J31: 0.25° x 0.25° | K31: 8-day | L31: 1982 - 2023 | M31: Open ocean, Surface | O31: Highlighting fine-scale and short-term variability of the ocean carbon sink | P31: A surface fCO₂ product with a 0.25° × 0.25° spatial resolution and an 8-day temporal resolution, providing estimates starting from 1982 (Gregor et al., 2024a; Gregor et al., 2024b). The high-resolution outputs are suitable for investigating the shorter- and finer-scale dynamics of surface fCO2. Despite sharing a name with its predecessor, OceanSODA-ETHZv2 does not provide TA estimates and employs a different methodology, as described in the following steps: 1) The atmospheric trend of CO2 is removed by subtracting marine boundary layer CO2 concentrations from SOCAT fCO2 producing a new target ∆*CO2 to reduce the biases at the start and end of the time-series. 2) An 8-day seasonal climatology of ∆*CO2 is estimated using Gradient Boosted Decision Trees (GBDT), which is later used as a predictor. 3) The non-seasonal thermal component is removed from ∆*CO2, resulting in a new target, ∆*CO2nonT. 4) The new target is estimated using a feed-forward neural network, with the GBDT as one of the forcing variables. 5) Steps 4 through to 1 are inverted to arrive at fCO2. 6) Air-sea CO2 fluxes are computed using ERA5 winds. | Q31: =getStatusCode(G31) -> 403 | R31: =getStatusCode(I31) -> 200
A32: 46031.76 | B32: Liqing.Jiang@noaa.gov | C32: Gridded surface | D32: LDEO-HPD fCO2 | E32: Gloege, L., Yan, M., Zheng, T., and McKinley, G. A.: Improved quantification of ocean carbon uptake by using machine learning to merge global models and pCO2 data, Journal of Advances in Modeling Earth Systems, 14(2), https://doi.org/10.1029/2021ms002620, 2022. | F32: Gloege et al. (2022) | G32: https://doi.org/10.1029/2021ms002620 | H32: https://i.ibb.co/pBXT90wP/jame21511-fig-0001-m.jpg | I32: https://zenodo.org/records/4760205 | J32: 1° x 1° | K32: monthly | L32: 1982-2018 | M32: Open ocean, Surface | O32: Temporal evolution of surface ocean fCO2 and air–sea CO2 exchange | P32: The LDEO Hybrid Physics Data (LDEO-HPD) estimates the temporal evolution of surface ocean fCO2 and air–sea CO2 exchange, utilizing the strengths of observations and global ocean biogeochemical models (GOBMs) (Gloege et al., 2022). GOBMs are internally consistent, mechanistic representations of the ocean circulation and carbon cycle, and have long been the standard for making spatiotemporally resolved estimates of air–sea CO2 fluxes. However, there is often a bias between the modeled fCO2 and available surface ocean measurements (Fay and McKinley 2021). The LDEO-HPD approach trains an eXtreme Gradient Boosting (XGB) algorithm to learn a non-linear relationship between model-data fCO2 mismatch and observed predictor variables: sea surface temperature (SST), sea surface salinity (SSS), chlorophyll concentration, mixed layer depth). The GOBM fCO2 is then corrected with the predicted model-data misfit to estimate real-world fCO2 for the observation period (Gloege et al., 2022). This results in reconstructed monthly surface ocean fCO2 and air–sea CO2 fluxes on a 1° × 1° grid in the open ocean beginning in 1982. | Q32: =getStatusCode(G32) -> 200 | R32: =getStatusCode(I32) -> 200
A33: 45973.959 | B33: afay@ldeo.columbia.edu | C33: Gridded surface | D33: LDEO-HPD fCO2, with Extended Temporal Coverage | E33: Gloege, L., Yan, M., Zheng, T. and McKinley, G. A.: Improved quantification of ocean carbon uptake by using machine learning to merge global models and pCO2 data, Journal of Advances in Modeling Earth Systems, 14(2), https://doi.org/10.1029/2021MS002620, 2022; </br></br>Bennington, V., Gloege, L., and McKinley, G. A.: Variability in the global ocean carbon sink from 1959 to 2020 by correcting models with observations, Geophysical Research Letters, 49(14), https://doi.org/10.1029/2022GL098632, 2022 | F33: Gloege et al. (2022), Bennington et al. (2022) | G33: https://doi.org/10.1029/2022GL098632 | H33: https://i.ibb.co/pBXT90wP/jame21511-fig-0001-m.jpg | I33: https://zenodo.org/records/13891722 | J33: 1° x 1° | K33: monthly | L33: 1959-2023 | M33: Open ocean | O33: LDEO-HPD uses model-data misfit climatology to extend estimate back in time to 1959 | P33: LDEO-HPD with Extended Temporal Coverage builds on the work of Gloege et al. (2022), the LDEO-HPD product, extending the timeseries back in time to predict fCO2 for all available model years. Bennington et al. (2022) find that the largest component of the GOBM corrections is climatological. The smaller corrections at other timescales suggest either that these are well captured by the GOBMs or the data are insufficient. The dominance of climatological corrections supports the extension of the LDEO-HPD fCO2 product backwards in time. A climatology of model-observation misfits for the best-observed period (2000–present) is applied to the GOBMs for 1959–1981, while an inter-annually varying correction is used for 1982 onward. (Bennington et al., 2022a). This results in reconstructed monthly surface ocean fCO2 and air–sea CO2 fluxes on a 1° × 1° grid covering the open ocean, beginning in 1959. | Q33: =getStatusCode(G33) -> 403 | R33: =getStatusCode(I33) -> 200
